{"cells":[{"cell_type":"markdown","source":"# Errors a.k.a. exceptions","metadata":{"tags":[],"cell_id":"00000-7ef95b81-b6cb-4e31-b934-01171d01e4b4","deepnote_cell_type":"markdown"}},{"cell_type":"markdown","source":"Errors in computing can be separated into *syntax errors* and *runtime errors*. Syntax errors are caused by e.g. unpaired brackets,\nwrong indentation, etc. A program with syntax errors can not run at all. More frequent are run-time errors that arise from\nan improper use of a function, missing data, network problems etc.\nSince Python is an interpreted, dynamically typed language, most errors will show up on the fly, as opposed to compiled languages,\nwhere a significant subset of errors is discovered during compilation.\n","metadata":{"cell_id":"00000-28f713e4-b8f1-478f-b7a5-94a918915e07","deepnote_cell_type":"markdown"}},{"cell_type":"markdown","source":"## Exceptions\n\nAn exception is thrown when something unexpected or utterly wrong happens in the program.\nIf we don't handle this exception (see below), the program is interrupted.\nE.g. division by zero throws an  `ZeroDivisionError` exception.","metadata":{"cell_id":"00001-118e560e-cd6d-4fcc-97e4-1165b5f227e5","deepnote_cell_type":"markdown"}},{"cell_type":"code","metadata":{"collapsed":false,"cell_id":"00002-160b2af8-6c93-41fb-b2ea-25cbeceb00f8","deepnote_to_be_reexecuted":false,"source_hash":"59423744","execution_start":1610272384819,"execution_millis":1132,"deepnote_cell_type":"code"},"source":"1/0","execution_count":null,"outputs":[{"output_type":"error","ename":"ZeroDivisionError","evalue":"division by zero","traceback":["\u001b[0;31m---------------------------------------------------------------------------\u001b[0m","\u001b[0;31mZeroDivisionError\u001b[0m                         Traceback (most recent call last)","\u001b[0;32m<ipython-input-1-9e1622b385b6>\u001b[0m in \u001b[0;36m<module>\u001b[0;34m\u001b[0m\n\u001b[0;32m----> 1\u001b[0;31m \u001b[0;36m1\u001b[0m\u001b[0;34m/\u001b[0m\u001b[0;36m0\u001b[0m\u001b[0;34m\u001b[0m\u001b[0;34m\u001b[0m\u001b[0m\n\u001b[0m","\u001b[0;31mZeroDivisionError\u001b[0m: division by zero"]}]},{"cell_type":"markdown","source":"## Catching exceptions\n\nIf you do not want to interrupt the program at the moment of an exception, you can use a `try` - `except` block.\nIt works so that the unsafe part of the code is placed under `try`, followed by an `except` block,\nwhich contains instructions in the case of an error (exception).\n","metadata":{"cell_id":"00003-f8d7ea95-485e-45f7-b9ef-f12176475ebd","deepnote_cell_type":"markdown"}},{"cell_type":"code","metadata":{"collapsed":false,"cell_id":"00004-02c52582-d9d0-400c-aa53-56a2fb769d19","deepnote_to_be_reexecuted":false,"source_hash":"495eed8c","execution_start":1610272402619,"execution_millis":1,"deepnote_cell_type":"code"},"source":"try:\n    1/0\nexcept:\n    print(\"Don't divide by zero!\")","execution_count":null,"outputs":[{"name":"stdout","text":"Don't divide by zero!\n","output_type":"stream"}]},{"cell_type":"markdown","source":"The `except` block used as above catches all exceptions. This is almost never a good idea.\nIt is advised to catch only specific types of exceptions (those that are expected and we\nknow what to do with them).\nTo catch the division by zero one would write:\n","metadata":{"cell_id":"00005-950741c5-51e1-4a84-8b91-ca85c7476a6c","deepnote_cell_type":"markdown"}},{"cell_type":"code","metadata":{"collapsed":false,"cell_id":"00006-c6e8c0f6-6766-4092-908b-20d882e6897f","deepnote_to_be_reexecuted":false,"source_hash":"6ac04e00","execution_start":1610272466119,"execution_millis":19,"deepnote_cell_type":"code"},"source":"try:\n    1/0\n# the error variable will contain the exception\nexcept ZeroDivisionError as error:\n    print(\"Don't divide by zero!\")\n    print(error)","execution_count":null,"outputs":[{"name":"stdout","text":"Don't divide by zero!\ndivision by zero\n","output_type":"stream"}]},{"cell_type":"markdown","source":"*Note: It may be tempting to handle all possible exceptions that can occur. But this makes sense\nonly when you really can solve the problem. If you don't know how to solve it, let the exception\npropagate up the function call hierarchy and perhaps the code there will know better. And if not,\nit's usually better when the application ends and the exception is reported (which is the default for\nuncaught exceptions).*","metadata":{"tags":[],"cell_id":"00008-9d9951b1-3c40-4fdc-ac32-8e4e0d3cbadb","deepnote_cell_type":"markdown"}},{"cell_type":"markdown","source":"Complete try-except block may also contain `else` and `finally` blocks, see\n[documentation](http://docs.python.org/2/reference/compound_stmts.html#try) .\n`finally` is especially useful for \"cleaning\", e.g. to close a file etc.\n","metadata":{"cell_id":"00007-a0c8a575-191f-431c-83a0-08486d5dd10e","deepnote_cell_type":"markdown"}},{"cell_type":"markdown","source":"## Raising exceptions\n\nExceptions can, of course, can also be thrown in our code using the `raise` keyword.\nFor example, checking the input of a function can be carried out like this:\n","metadata":{"cell_id":"00008-2b389a41-0dbe-418c-b390-bc3358f07841","deepnote_cell_type":"markdown"}},{"cell_type":"code","metadata":{"collapsed":false,"cell_id":"00009-0ce4c74b-9950-4e67-baf0-7ee6f8a6097c","deepnote_to_be_reexecuted":false,"source_hash":"3c839974","execution_millis":0,"execution_start":1610272568851,"deepnote_cell_type":"code"},"source":"def fact(n):\n    \"\"\"Calculates the factorial\n    \"\"\"\n    from math import factorial\n    try:\n        # try to convert n to a number\n        n = float(n)\n    except ValueError as e:\n        raise ValueError(f\"{n} is not a number\")\n    # is n integer >= 0\n    if not n.is_integer() or n < 0:\n        raise ValueError(f\"{n} is not an integer >= 0\")\n    return factorial(n)\n\n# let's test the function\nn = 4\nprint(f\"{n}! = {fact(n)}\")","execution_count":null,"outputs":[{"name":"stdout","text":"4! = 24\n","output_type":"stream"}]},{"cell_type":"code","metadata":{"collapsed":false,"cell_id":"00010-830ba6e7-8a83-4eed-8423-088d71fc0606","deepnote_to_be_reexecuted":false,"source_hash":"b5d6debe","execution_millis":0,"execution_start":1610272577687,"deepnote_cell_type":"code"},"source":"# do the exeptions work?\nfor n in (4.0, \"0\", \"zero\", 3.2, -1):\n    try:\n        print(f\"{n}! = {fact(n)}\")\n    # the Exception class covers almost any exception\n    except Exception as e:\n        print(e)","execution_count":null,"outputs":[{"name":"stdout","text":"4.0! = 24\n0! = 1\nzero is not a number\n3.2 is not an integer >= 0\n-1.0 is not an integer >= 0\n","output_type":"stream"}]},{"cell_type":"markdown","source":"## Traceback\n\nThe [`traceback`](https://docs.python.org/3/library/traceback.html) module provides means to discover the exception origin. Let's demonstrate the `print_exc` function:","metadata":{"cell_id":"00011-86306f2c-db08-4168-a5c2-1fe2c5dc73de","deepnote_cell_type":"markdown"}},{"cell_type":"code","metadata":{"collapsed":false,"cell_id":"00012-5205b434-118a-42a2-a8fe-4dbe328e4ed5","deepnote_to_be_reexecuted":false,"source_hash":"c698f70","execution_millis":0,"execution_start":1610272626423,"deepnote_cell_type":"code"},"source":"import traceback, sys\n\ntry:\n    fact(1.1)\nexcept Exception:\n    traceback.print_exc(file=sys.stdout)\n\ntry:\n    fact(1.1e100)  # Number a bit too big?\nexcept Exception:\n    traceback.print_exc(file=sys.stdout)","execution_count":null,"outputs":[{"name":"stdout","text":"Traceback (most recent call last):\n  File \"<ipython-input-6-0dc9bca0426c>\", line 4, in <module>\n    fact(1.1)\n  File \"<ipython-input-4-0edb312e713b>\", line 12, in fact\n    raise ValueError(f\"{n} is not an integer >= 0\")\nValueError: 1.1 is not an integer >= 0\nTraceback (most recent call last):\n  File \"<ipython-input-6-0dc9bca0426c>\", line 9, in <module>\n    fact(1.1e100)  # Number a bit too big?\n  File \"<ipython-input-4-0edb312e713b>\", line 13, in fact\n    return factorial(n)\nOverflowError: factorial() argument should not exceed 9223372036854775807\n","output_type":"stream"}]},{"cell_type":"markdown","source":"## User-defined exception types (optional)\n\nIt is usually not necessary, but it possible to defined new classes that represent\nspecial kinds of exception. The main advantage is that you may fine-tune the `except`\nclause to handle only a narrowly specified subset of potential problems.\n\nThe simplest user-defined exception looks like this:","metadata":{"tags":[],"cell_id":"00014-59447ef7-2832-4ab6-ad88-679099ee519a","deepnote_cell_type":"markdown"}},{"cell_type":"code","metadata":{"tags":[],"cell_id":"00016-f0f25454-9e32-4680-95d0-5f2c938e5705","deepnote_to_be_reexecuted":false,"source_hash":"35ba7bdd","execution_millis":1,"execution_start":1610272666863,"deepnote_cell_type":"code"},"source":"class HumanError(Exception):\n    pass  # We don't need any code here.\n\n\nraise HumanError(\"You made a serious mistake!\")","execution_count":null,"outputs":[{"output_type":"error","ename":"HumanError","evalue":"You made a serious mistake!","traceback":["\u001b[0;31m---------------------------------------------------------------------------\u001b[0m","\u001b[0;31mHumanError\u001b[0m                                Traceback (most recent call last)","\u001b[0;32m<ipython-input-7-f09d930a8ea5>\u001b[0m in \u001b[0;36m<module>\u001b[0;34m\u001b[0m\n\u001b[1;32m      3\u001b[0m \u001b[0;34m\u001b[0m\u001b[0m\n\u001b[1;32m      4\u001b[0m \u001b[0;34m\u001b[0m\u001b[0m\n\u001b[0;32m----> 5\u001b[0;31m \u001b[0;32mraise\u001b[0m \u001b[0mHumanError\u001b[0m\u001b[0;34m(\u001b[0m\u001b[0;34m\"You made a serious mistake!\"\u001b[0m\u001b[0;34m)\u001b[0m\u001b[0;34m\u001b[0m\u001b[0;34m\u001b[0m\u001b[0m\n\u001b[0m","\u001b[0;31mHumanError\u001b[0m: You made a serious mistake!"]}]},{"cell_type":"markdown","source":"More on this topic in the official [documentation](https://docs.python.org/3/tutorial/errors.html#user-defined-exceptions).","metadata":{"tags":[],"cell_id":"00016-7f9b7b32-f0d4-4013-9ec5-adb1ed1d64d9","deepnote_cell_type":"markdown"}}],"nbformat":4,"nbformat_minor":0,"metadata":{"kernelspec":{"display_name":"Python 3","language":"python","name":"python3"},"language_info":{"codemirror_mode":{"name":"ipython","version":3},"file_extension":".py","mimetype":"text/x-python","name":"python","nbconvert_exporter":"python","pygments_lexer":"ipython3","version":"3.4.3"},"deepnote_notebook_id":"b0a23667-cc8c-4579-bd94-99339dfaac86","deepnote_execution_queue":[]}}